Workbook
Name Print_Titles: 'lamp. sk'!A:H,'lamp. sk'!$A$11:$IV$11
Name Print_Titles: 'rekap hitungan'!B:K,'rekap hitungan'!$A$21:$IV$21
Name Print_Titles: perbandingan!B:F,perbandingan!$A$13:$IV$13
Name Print_Area: perbandingan!$B$1:$F$122
Name Print_Area: 'lamp. sk'!$A$1:$H$126
Name Print_Area: 'hitung kewenangan kegiatan'!$B$1:$P$130
Name Print_Area: 'rekap hitungan'!$B$1:$K$130
Name Print_Titles: 'hitung kewenangan kegiatan'!$A$3:$IV$5
Name Print_Area: 'hitung siltap'!$B$1:$X$124
Name Print_Area: 'checklist add & premi 26'!$B$2:$E$18
Name Print_Area: 'hitung premi dpa pmk'!$B$1:$H$19

Sheet hitung siltap
B2: SIMULASI PERHITUNGAN ADD SILTAP LURAH DAN PAMONG KALURAHAN
B3: Lampiran I
B4: Nomor Surat:
B5: Tanggal:
B7: SIMULASI PERHITUNGAN ADD SILTAP LURAH DAN PAMONG KALURAHAN TAHUN 2026
B9: Asumsi:
B10: 1. | C10: Siltap naik untuk tiap-tiap Lurah & Pamong
C11: Lurah | D11: 3625000 | E11: + | F11: 650000 | G11: = | H11: =D11+F11 -> 4275000
C12: Carik | D12: 2675000 | E12: + | F12: 625000 | G12: = | H12: =D12+F12 -> 3300000
C13: Kasi/Kaur | D13: 2375000 | E13: + | F13: 625000 | G13: = | H13: =D13+F13 -> 3000000
C14: Dukuh | D14: 2275000 | E14: + | F14: 625000 | G14: = | H14: =D14+F14 -> 2900000
B16: 2. | C16: Asumsi UMK 2026 | D16: 2624400
B18: NO | C18: KAPANEWON/KALURAHAN | D18: SILTAP PER BULAN | H18: JUMLAH DUKUH | I18: SILTAP PER TAHUN | N18: BPJS KES STAF | Q18: BPJS NAKER LURAH & PAMONG KALURAHAN | V18: BPJS NAKER STAF | W18: BPJS NAKER TOTAL | X18: ADD KEBIJAKAN (THR & BANTUAN PENDIDIKAN/GAJI KE-13)
D19: LURAH | E19: CARIK | F19: KASI/KAUR | G19: DUKUH | I19: LURAH | J19: CARIK | K19: KASI/KAUR | L19: DUKUH | M19: JUMLAH | N19: 1 org/bln | O19: 8 org/bln | P19: 8 org/12 bln | Q19: LURAH | R19: CARIK | S19: KASI/KAUR | T19: DUKUH | U19: JUMLAH
B20: 1 | C20: 2 | D20: 3 | E20: 4 | F20: 5 | G20: 6 | H20: 7 | I20: 8=3x12 bln | J20: 9=4x12 bln | K20: 10=5x12 bln | L20: 11=6x12 bln | M20: 12=8+9+10+11 | N20: 13=UMKx4% | O20: 14=13x8 org | P20: 15=14x12 bln | Q20: 16=3x6,24%x12 bln | R20: 17=4x6,24%x12 bln | S20: 18=5x6,24%x12 bln | T20: 19=6x6,24%x12 bln | U20: 20=16+17+18+19 | V20: 21=UMKx6,24%x8 orgx12 bln | W20: 22=20+21 | X20: 23=(3x2 bln)+(4x2 bln)+(5x2 bln)+(6x2 bln)
B21: I. | C21: GAMPING
B22: 1 | C22: Balecatur | D22: =$H$11 -> 4275000 | E22: =$H$12 -> 3300000 | F22: =$H$13 -> 3000000 | G22: =$H$14 -> 2900000 | H22: 18 | I22: =D22*12 -> 51300000 | J22: =E22*12 -> 39600000 | K22: =F22*6*12 -> 216000000 | L22: =G22*H22*12 -> 626400000 | M22: =SUM(I22:L22) -> 933300000 | N22: =$E$135*$E$137 -> 104976 | O22: =N22*8 -> 839808 | P22: =O22*12 -> 10077696 | Q22: =SUM(D22*$E$143)*12 -> 3201120 | R22: =SUM(E22*$E$143)*12 -> 2471040 | S22: =SUM(F22*$E$143*6)*12 -> 13478400 | T22: =SUM(G22*$E$143*H22)*12 -> 39087360 | U22: =SUM(Q22:T22) -> 58237920 | V22: =SUM($E$135*$E$143*8)*12 -> 15721206 | W22: =SUM(U22+V22) -> 73959126 | X22: =SUM(D22*2)+(E22*2)+(F22*6*2)+(G22*H22*2) -> 155550000
B23: 2 | C23: Ambarketawang | D23: =$H$11 -> 4275000 | E23: =$H$12 -> 3300000 | F23: =$H$13 -> 3000000 | G23: =$H$14 -> 2900000 | H23: 13 | I23: =D23*12 -> 51300000 | J23: =E23*12 -> 39600000 | K23: =F23*6*12 -> 216000000 | L23: =G23*H23*12 -> 452400000 | M23: =SUM(I23:L23) -> 759300000 | N23: =$E$135*$E$137 -> 104976 | O23: =N23*8 -> 839808 | P23: =O23*12 -> 10077696 | Q23: =SUM(D23*$E$143)*12 -> 3201120 | R23: =SUM(E23*$E$143)*12 -> 2471040 | S23: =SUM(F23*$E$143*6)*12 -> 13478400 | T23: =SUM(G23*$E$143*H23)*12 -> 28229760 | U23: =SUM(Q23:T23) -> 47380320 | V23: =SUM($E$135*$E$143*8)*12 -> 15721206 | W23: =SUM(U23+V23) -> 63101526 | X23: =SUM(D23*2)+(E23*2)+(F23*6*2)+(G23*H23*2) -> 126550000
B24: 3 | C24: Banyuraden | D24: =$H$11 -> 4275000 | E24: =$H$12 -> 3300000 | F24: =$H$13 -> 3000000 | G24: =$H$14 -> 2900000 | H24: 8 | I24: =D24*12 -> 51300000 | J24: =E24*12 -> 39600000 | K24: =F24*6*12 -> 216000000 | L24: =G24*H24*12 -> 278400000 | M24: =SUM(I24:L24) -> 585300000 | N24: =$E$135*$E$137 -> 104976 | O24: =N24*8 -> 839808 | P24: =O24*12 -> 10077696 | Q24: =SUM(D24*$E$143)*12 -> 3201120 | R24: =SUM(E24*$E$143)*12 -> 2471040 | S24: =SUM(F24*$E$143*6)*12 -> 13478400 | T24: =SUM(G24*$E$143*H24)*12 -> 17372160 | U24: =SUM(Q24:T24) -> 36522720 | V24: =SUM($E$135*$E$143*8)*12 -> 15721206 | W24: =SUM(U24+V24) -> 52243926 | X24: =SUM(D24*2)+(E24*2)+(F24*6*2)+(G24*H24*2) -> 97550000
B25: 4 | C25: Nogotirto | D25: =$H$11 -> 4275000 | E25: =$H$12 -> 3300000 | F25: =$H$13 -> 3000000 | G25: =$H$14 -> 2900000 | H25: 8 | I25: =D25*12 -> 51300000 | J25: =E25*12 -> 39600000 | K25: =F25*6*12 -> 216000000 | L25: =G25*H25*12 -> 278400000 | M25: =SUM(I25:L25) -> 585300000 | N25: =$E$135*$E$137 -> 104976 | O25: =N25*8 -> 839808 | P25: =O25*12 -> 10077696 | Q25: =SUM(D25*$E$143)*12 -> 3201120 | R25: =SUM(E25*$E$143)*12 -> 2471040 | S25: =SUM(F25*$E$143*6)*12 -> 13478400 | T25: =SUM(G25*$E$143*H25)*12 -> 17372160 | U25: =SUM(Q25:T25) -> 36522720 | V25: =SUM($E$135*$E$143*8)*12 -> 15721206 | W25: =SUM(U25+V25) -> 52243926 | X25: =SUM(D25*2)+(E25*2)+(F25*6*2)+(G25*H25*2) -> 97550000
B26: 5 | C26: Trihanggo | D26: =$H$11 -> 4275000 | E26: =$H$12 -> 3300000 | F26: =$H$13 -> 3000000 | G26: =$H$14 -> 2900000 | H26: 12 | I26: =D26*12 -> 51300000 | J26: =E26*12 -> 39600000 | K26: =F26*6*12 -> 216000000 | L26: =G26*H26*12 -> 417600000 | M26: =SUM(I26:L26) -> 724500000 | N26: =$E$135*$E$137 -> 104976 | O26: =N26*8 -> 839808 | P26: =O26*12 -> 10077696 | Q26: =SUM(D26*$E$143)*12 -> 3201120 | R26: =SUM(E26*$E$143)*12 -> 2471040 | S26: =SUM(F26*$E$143*6)*12 -> 13478400 | T26: =SUM(G26*$E$143*H26)*12 -> 26058240 | U26: =SUM(Q26:T26) -> 45208800 | V26: =SUM($E$135*$E$143*8)*12 -> 15721206 | W26: =SUM(U26+V26) -> 60930006 | X26: =SUM(D26*2)+(E26*2)+(F26*6*2)+(G26*H26*2) -> 120750000
B27: II. | C27: GODEAN
B28: 6 | C28: Sidorejo | D28: =$H$11 -> 4275000 | E28: =$H$12 -> 3300000 | F28: =$H$13 -> 3000000 | G28: =$H$14 -> 2900000 | H28: 13 | I28: =D28*12 -> 51300000 | J28: =E28*12 -> 39600000 | K28: =F28*6*12 -> 216000000 | L28: =G28*H28*12 -> 452400000 | M28: =SUM(I28:L28) -> 759300000 | N28: =$E$135*$E$137 -> 104976 | O28: =N28*8 -> 839808 | P28: =O28*12 -> 10077696 | Q28: =SUM(D28*$E$143)*12 -> 3201120 | R28: =SUM(E28*$E$143)*12 -> 2471040 | S28: =SUM(F28*$E$143*6)*12 -> 13478400 | T28: =SUM(G28*$E$143*H28)*12 -> 28229760 | U28: =SUM(Q28:T28) -> 47380320 | V28: =SUM($E$135*$E$143*8)*12 -> 15721206 | W28: =SUM(U28+V28) -> 63101526 | X28: =SUM(D28*2)+(E28*2)+(F28*6*2)+(G28*H28*2) -> 126550000
B29: 7 | C29: Sidoluhur | D29: =$H$11 -> 4275000 | E29: =$H$12 -> 3300000 | F29: =$H$13 -> 3000000 | G29: =$H$14 -> 2900000 | H29: 15 | I29: =D29*12 -> 51300000 | J29: =E29*12 -> 39600000 | K29: =F29*6*12 -> 216000000 | L29: =G29*H29*12 -> 522000000 | M29: =SUM(I29:L29) -> 828900000 | N29: =$E$135*$E$137 -> 104976 | O29: =N29*8 -> 839808 | P29: =O29*12 -> 10077696 | Q29: =SUM(D29*$E$143)*12 -> 3201120 | R29: =SUM(E29*$E$143)*12 -> 2471040 | S29: =SUM(F29*$E$143*6)*12 -> 13478400 | T29: =SUM(G29*$E$143*H29)*12 -> 32572800 | U29: =SUM(Q29:T29) -> 51723360 | V29: =SUM($E$135*$E$143*8)*12 -> 15721206 | W29: =SUM(U29+V29) -> 67444566 | X29: =SUM(D29*2)+(E29*2)+(F29*6*2)+(G29*H29*2) -> 138150000
B30: 8 | C30: Sidomulyo | D30: =$H$11 -> 4275000 | E30: =$H$12 -> 3300000 | F30: =$H$13 -> 3000000 | G30: =$H$14 -> 2900000 | H30: 8 | I30: =D30*12 -> 51300000 | J30: =E30*12 -> 39600000 | K30: =F30*6*12 -> 216000000 | L30: =G30*H30*12 -> 278400000 | M30: =SUM(I30:L30) -> 585300000 | N30: =$E$135*$E$137 -> 104976 | O30: =N30*8 -> 839808 | P30: =O30*12 -> 10077696 | Q30: =SUM(D30*$E$143)*12 -> 3201120 | R30: =SUM(E30*$E$143)*12 -> 2471040 | S30: =SUM(F30*$E$143*6)*12 -> 13478400 | T30: =SUM(G30*$E$143*H30)*12 -> 17372160 | U30: =SUM(Q30:T30) -> 36522720 | V30: =SUM($E$135*$E$143*8)*12 -> 15721206 | W30: =SUM(U30+V30) -> 52243926 | X30: =SUM(D30*2)+(E30*2)+(F30*6*2)+(G30*H30*2) -> 97550000
B31: 9 | C31: Sidoagung | D31: =$H$11 -> 4275000 | E31: =$H$12 -> 3300000 | F31: =$H$13 -> 3000000 | G31: =$H$14 -> 2900000 | H31: 8 | I31: =D31*12 -> 51300000 | J31: =E31*12 -> 39600000 | K31: =F31*6*12 -> 216000000 | L31: =G31*H31*12 -> 278400000 | M31: =SUM(I31:L31) -> 585300000 | N31: =$E$135*$E$137 -> 104976 | O31: =N31*8 -> 839808 | P31: =O31*12 -> 10077696 | Q31: =SUM(D31*$E$143)*12 -> 3201120 | R31: =SUM(E31*$E$143)*12 -> 2471040 | S31: =SUM(F31*$E$143*6)*12 -> 13478400 | T31: =SUM(G31*$E$143*H31)*12 -> 17372160 | U31: =SUM(Q31:T31) -> 36522720 | V31: =SUM($E$135*$E$143*8)*12 -> 15721206 | W31: =SUM(U31+V31) -> 52243926 | X31: =SUM(D31*2)+(E31*2)+(F31*6*2)+(G31*H31*2) -> 97550000
B32: 10 | C32: Sidokarto | D32: =$H$11 -> 4275000 | E32: =$H$12 -> 3300000 | F32: =$H$13 -> 3000000 | G32: =$H$14 -> 2900000 | H32: 14 | I32: =D32*12 -> 51300000 | J32: =E32*12 -> 39600000 | K32: =F32*6*12 -> 216000000 | L32: =G32*H32*12 -> 487200000 | M32: =SUM(I32:L32) -> 794100000 | N32: =$E$135*$E$137 -> 104976 | O32: =N32*8 -> 839808 | P32: =O32*12 -> 10077696 | Q32: =SUM(D32*$E$143)*12 -> 3201120 | R32: =SUM(E32*$E$143)*12 -> 2471040 | S32: =SUM(F32*$E$143*6)*12 -> 13478400 | T32: =SUM(G32*$E$143*H32)*12 -> 30401280 | U32: =SUM(Q32:T32) -> 49551840 | V32: =SUM($E$135*$E$143*8)*12 -> 15721206 | W32: =SUM(U32+V32) -> 65273046 | X32: =SUM(D32*2)+(E32*2)+(F32*6*2)+(G32*H32*2) -> 132350000
B33: 11 | C33: Sidoarum | D33: =$H$11 -> 4275000 | E33: =$H$12 -> 3300000 | F33: =$H$13 -> 3000000 | G33: =$H$14 -> 2900000 | H33: 8 | I33: =D33*12 -> 51300000 | J33: =E33*12 -> 39600000 | K33: =F33*6*12 -> 216000000 | L33: =G33*H33*12 -> 278400000 | M33: =SUM(I33:L33) -> 585300000 | N33: =$E$135*$E$137 -> 104976 | O33: =N33*8 -> 839808 | P33: =O33*12 -> 10077696 | Q33: =SUM(D33*$E$143)*12 -> 3201120 | R33: =SUM(E33*$E$143)*12 -> 2471040 | S33: =SUM(F33*$E$143*6)*12 -> 13478400 | T33: =SUM(G33*$E$143*H33)*12 -> 17372160 | U33: =SUM(Q33:T33) -> 36522720 | V33: =SUM($E$135*$E$143*8)*12 -> 15721206 | W33: =SUM(U33+V33) -> 52243926 | X33: =SUM(D33*2)+(E33*2)+(F33*6*2)+(G33*H33*2) -> 97550000
B34: 12 | C34: Sidomoyo | D34: =$H$11 -> 4275000 | E34: =$H$12 -> 3300000 | F34: =$H$13 -> 3000000 | G34: =$H$14 -> 2900000 | H34: 11 | I34: =D34*12 -> 51300000 | J34: =E34*12 -> 39600000 | K34: =F34*6*12 -> 216000000 | L34: =G34*H34*12 -> 382800000 | M34: =SUM(I34:L34) -> 689700000 | N34: =$E$135*$E$137 -> 104976 | O34: =N34*8 -> 839808 | P34: =O34*12 -> 10077696 | Q34: =SUM(D34*$E$143)*12 -> 3201120 | R34: =SUM(E34*$E$143)*12 -> 2471040 | S34: =SUM(F34*$E$143*6)*12 -> 13478400 | T34: =SUM(G34*$E$143*H34)*12 -> 23886720 | U34: =SUM(Q34:T34) -> 43037280 | V34: =SUM($E$135*$E$143*8)*12 -> 15721206 | W34: =SUM(U34+V34) -> 58758486 | X34: =SUM(D34*2)+(E34*2)+(F34*6*2)+(G34*H34*2) -> 114950000
B35: III. | C35: MOYUDAN
B36: 13 | C36: Sumberrrahayu | D36: =$H$11 -> 4275000 | E36: =$H$12 -> 3300000 | F36: =$H$13 -> 3000000 | G36: =$H$14 -> 2900000 | H36: 15 | I36: =D36*12 -> 51300000 | J36: =E36*12 -> 39600000 | K36: =F36*6*12 -> 216000000 | L36: =G36*H36*12 -> 522000000 | M36: =SUM(I36:L36) -> 828900000 | N36: =$E$135*$E$137 -> 104976 | O36: =N36*8 -> 839808 | P36: =O36*12 -> 10077696 | Q36: =SUM(D36*$E$143)*12 -> 3201120 | R36: =SUM(E36*$E$143)*12 -> 2471040 | S36: =SUM(F36*$E$143*6)*12 -> 13478400 | T36: =SUM(G36*$E$143*H36)*12 -> 32572800 | U36: =SUM(Q36:T36) -> 51723360 | V36: =SUM($E$135*$E$143*8)*12 -> 15721206 | W36: =SUM(U36+V36) -> 67444566 | X36: =SUM(D36*2)+(E36*2)+(F36*6*2)+(G36*H36*2) -> 138150000
B37: 14 | C37: Sumbersari | D37: =$H$11 -> 4275000 | E37: =$H$12 -> 3300000 | F37: =$H$13 -> 3000000 | G37: =$H$14 -> 2900000 | H37: 13 | I37: =D37*12 -> 51300000 | J37: =E37*12 -> 39600000 | K37: =F37*6*12 -> 216000000 | L37: =G37*H37*12 -> 452400000 | M37: =SUM(I37:L37) -> 759300000 | N37: =$E$135*$E$137 -> 104976 | O37: =N37*8 -> 839808 | P37: =O37*12 -> 10077696 | Q37: =SUM(D37*$E$143)*12 -> 3201120 | R37: =SUM(E37*$E$143)*12 -> 2471040 | S37: =SUM(F37*$E$143*6)*12 -> 13478400 | T37: =SUM(G37*$E$143*H37)*12 -> 28229760 | U37: =SUM(Q37:T37) -> 47380320 | V37: =SUM($E$135*$E$143*8)*12 -> 15721206 | W37: =SUM(U37+V37) -> 63101526 | X37: =SUM(D37*2)+(E37*2)+(F37*6*2)+(G37*H37*2) -> 126550000
B38: 15 | C38: Sumberagung | D38: =$H$11 -> 4275000 | E38: =$H$12 -> 3300000 | F38: =$H$13 -> 3000000 | G38: =$H$14 -> 2900000 | H38: 21 | I38: =D38*12 -> 51300000 | J38: =E38*12 -> 39600000 | K38: =F38*6*12 -> 216000000 | L38: =G38*H38*12 -> 730800000 | M38: =SUM(I38:L38) -> 1037700000 | N38: =$E$135*$E$137 -> 104976 | O38: =N38*8 -> 839808 | P38: =O38*12 -> 10077696 | Q38: =SUM(D38*$E$143)*12 -> 3201120 | R38: =SUM(E38*$E$143)*12 -> 2471040 | S38: =SUM(F38*$E$143*6)*12 -> 13478400 | T38: =SUM(G38*$E$143*H38)*12 -> 45601920 | U38: =SUM(Q38:T38) -> 64752480 | V38: =SUM($E$135*$E$143*8)*12 -> 15721206 | W38: =SUM(U38+V38) -> 80473686 | X38: =SUM(D38*2)+(E38*2)+(F38*6*2)+(G38*H38*2) -> 172950000
B39: 16 | C39: Sumberarum | D39: =$H$11 -> 4275000 | E39: =$H$12 -> 3300000 | F39: =$H$13 -> 3000000 | G39: =$H$14 -> 2900000 | H39: 16 | I39: =D39*12 -> 51300000 | J39: =E39*12 -> 39600000 | K39: =F39*6*12 -> 216000000 | L39: =G39*H39*12 -> 556800000 | M39: =SUM(I39:L39) -> 863700000 | N39: =$E$135*$E$137 -> 104976 | O39: =N39*8 -> 839808 | P39: =O39*12 -> 10077696 | Q39: =SUM(D39*$E$143)*12 -> 3201120 | R39: =SUM(E39*$E$143)*12 -> 2471040 | S39: =SUM(F39*$E$143*6)*12 -> 13478400 | T39: =SUM(G39*$E$143*H39)*12 -> 34744320 | U39: =SUM(Q39:T39) -> 53894880 | V39: =SUM($E$135*$E$143*8)*12 -> 15721206 | W39: =SUM(U39+V39) -> 69616086 | X39: =SUM(D39*2)+(E39*2)+(F39*6*2)+(G39*H39*2) -> 143950000
B40: IV. | C40: MINGGIR
B41: 17 | C41: Sendangarum | D41: =$H$11 -> 4275000 | E41: =$H$12 -> 3300000 | F41: =$H$13 -> 3000000 | G41: =$H$14 -> 2900000 | H41: 9 | I41: =D41*12 -> 51300000 | J41: =E41*12 -> 39600000 | K41: =F41*6*12 -> 216000000 | L41: =G41*H41*12 -> 313200000 | M41: =SUM(I41:L41) -> 620100000 | N41: =$E$135*$E$137 -> 104976 | O41: =N41*8 -> 839808 | P41: =O41*12 -> 10077696 | Q41: =SUM(D41*$E$143)*12 -> 3201120 | R41: =SUM(E41*$E$143)*12 -> 2471040 | S41: =SUM(F41*$E$143*6)*12 -> 13478400 | T41: =SUM(G41*$E$143*H41)*12 -> 19543680 | U41: =SUM(Q41:T41) -> 38694240 | V41: =SUM($E$135*$E$143*8)*12 -> 15721206 | W41: =SUM(U41+V41) -> 54415446 | X41: =SUM(D41*2)+(E41*2)+(F41*6*2)+(G41*H41*2) -> 103350000
B42: 18 | C42: Sendangmulyo | D42: =$H$11 -> 4275000 | E42: =$H$12 -> 3300000 | F42: =$H$13 -> 3000000 | G42: =$H$14 -> 2900000 | H42: 16 | I42: =D42*12 -> 51300000 | J42: =E42*12 -> 39600000 | K42: =F42*6*12 -> 216000000 | L42: =G42*H42*12 -> 556800000 | M42: =SUM(I42:L42) -> 863700000 | N42: =$E$135*$E$137 -> 104976 | O42: =N42*8 -> 839808 | P42: =O42*12 -> 10077696 | Q42: =SUM(D42*$E$143)*12 -> 3201120 | R42: =SUM(E42*$E$143)*12 -> 2471040 | S42: =SUM(F42*$E$143*6)*12 -> 13478400 | T42: =SUM(G42*$E$143*H42)*12 -> 34744320 | U42: =SUM(Q42:T42) -> 53894880 | V42: =SUM($E$135*$E$143*8)*12 -> 15721206 | W42: =SUM(U42+V42) -> 69616086 | X42: =SUM(D42*2)+(E42*2)+(F42*6*2)+(G42*H42*2) -> 143950000
B43: 19 | C43: Sendangagung | D43: =$H$11 -> 4275000 | E43: =$H$12 -> 3300000 | F43: =$H$13 -> 3000000 | G43: =$H$14 -> 2900000 | H43: 15 | I43: =D43*12 -> 51300000 | J43: =E43*12 -> 39600000 | K43: =F43*6*12 -> 216000000 | L43: =G43*H43*12 -> 522000000 | M43: =SUM(I43:L43) -> 828900000 | N43: =$E$135*$E$137 -> 104976 | O43: =N43*8 -> 839808 | P43: =O43*12 -> 10077696 | Q43: =SUM(D43*$E$143)*12 -> 3201120 | R43: =SUM(E43*$E$143)*12 -> 2471040 | S43: =SUM(F43*$E$143*6)*12 -> 13478400 | T43: =SUM(G43*$E$143*H43)*12 -> 32572800 | U43: =SUM(Q43:T43) -> 51723360 | V43: =SUM($E$135*$E$143*8)*12 -> 15721206 | W43: =SUM(U43+V43) -> 67444566 | X43: =SUM(D43*2)+(E43*2)+(F43*6*2)+(G43*H43*2) -> 138150000
B44: 20 | C44: Sendangsari | D44: =$H$11 -> 4275000 | E44: =$H$12 -> 3300000 | F44: =$H$13 -> 3000000 | G44: =$H$14 -> 2900000 | H44: 12 | I44: =D44*12 -> 51300000 | J44: =E44*12 -> 39600000 | K44: =F44*6*12 -> 216000000 | L44: =G44*H44*12 -> 417600000 | M44: =SUM(I44:L44) -> 724500000 | N44: =$E$135*$E$137 -> 104976 | O44: =N44*8 -> 839808 | P44: =O44*12 -> 10077696 | Q44: =SUM(D44*$E$143)*12 -> 3201120 | R44: =SUM(E44*$E$143)*12 -> 2471040 | S44: =SUM(F44*$E$143*6)*12 -> 13478400 | T44: =SUM(G44*$E$143*H44)*12 -> 26058240 | U44: =SUM(Q44:T44) -> 45208800 | V44: =SUM($E$135*$E$143*8)*12 -> 15721206 | W44: =SUM(U44+V44) -> 60930006 | X44: =SUM(D44*2)+(E44*2)+(F44*6*2)+(G44*H44*2) -> 120750000
B45: 21 | C45: Sendangrejo | D45: =$H$11 -> 4275000 | E45: =$H$12 -> 3300000 | F45: =$H$13 -> 3000000 | G45: =$H$14 -> 2900000 | H45: 16 | I45: =D45*12 -> 51300000 | J45: =E45*12 -> 39600000 | K45: =F45*6*12 -> 216000000 | L45: =G45*H45*12 -> 556800000 | M45: =SUM(I45:L45) -> 863700000 | N45: =$E$135*$E$137 -> 104976 | O45: =N45*8 -> 839808 | P45: =O45*12 -> 10077696 | Q45: =SUM(D45*$E$143)*12 -> 3201120 | R45: =SUM(E45*$E$143)*12 -> 2471040 | S45: =SUM(F45*$E$143*6)*12 -> 13478400 | T45: =SUM(G45*$E$143*H45)*12 -> 34744320 | U45: =SUM(Q45:T45) -> 53894880 | V45: =SUM($E$135*$E$143*8)*12 -> 15721206 | W45: =SUM(U45+V45) -> 69616086 | X45: =SUM(D45*2)+(E45*2)+(F45*6*2)+(G45*H45*2) -> 143950000
...

Sheet hitung kewenangan kegiatan
B1: TABEL HITUNG BESARAN ALOKASI DANA DESA KEWENANGAN KEGIATAN TAHUN 2026
B3: NO. | C3: KAPANEWON/KALURAHAN | E3: JML PADUKUHAN | G3: PENDUDUK MISKIN | I3: LUAS WILAYAH | K3: JUMLAH PENDUDUK | M3: INDEKS KSLTN GEO. | O3: BESARAN ADD KEWENANGAN KEGIATAN | P3: BESARAN ADD (Pembulatan)
D4: BOBOT | E4: BVJPad | F4: 0.3 | G4: BVPM | H4: 0.2 | I4: BVLW | J4: 0.2 | K4: BVJP | L4: 0.2 | M4: BVIKG | N4: 0.1
E5: PADUKUHAN | F5: KVJPad | G5: ORANG | H5: KVPM | I5: Ha | J5: KVLW | K5: JIWA | L5: KVJP | M5: Indeks | N5: KVIKG
B6: I. | C6: GAMPING
B7: 1 | C7: Balecatur | D7: =SUM((F7*$F$4)+(H7*$H$4)+($J$4*J7)+($L$4*L7)+($N$4*N7)) -> 0.015631758 | E7: 18 | F7: =E7/$E$126 -> 0.014851485 | G7: 1499 | H7: =G7/$G$126 -> 0.017117343 | I7: 968 | J7: =SUM(I7/I126) -> 0.016982277 | K7: 20830 | L7: =SUM(K7/K126) -> 0.018438034 | M7: 11.413181 | N7: =SUM(M7/M126) -> 0.0066878158 | O7: =D7*$O$129 -> 6.8991944e+08 | P7: =ROUNDUP(O7,0) -> 689919442
B8: 2 | C8: Ambarketawang | D8: =SUM((F8*$F$4)+(H8*$H$4)+($J$4*J8)+($L$4*L8)+($N$4*N8)) -> 0.014098022 | E8: 13 | F8: =E8/$E$126 -> 0.010726073 | G8: 1702 | H8: =G8/$G$126 -> 0.019435436 | I8: 628 | J8: =SUM(I8/I126) -> 0.011017428 | K8: 22918 | L8: =SUM(K8/K126) -> 0.020286263 | M8: 12.498432 | N8: =SUM(M8/M126) -> 0.0073237439 | O8: =D8*$O$129 -> 6.2222682e+08 | P8: =ROUNDUP(O8,0) -> 622226824
B9: 3 | C9: Banyuraden | D9: =SUM((F9*$F$4)+(H9*$H$4)+($J$4*J9)+($L$4*L9)+($N$4*N9)) -> 0.01022593 | E9: 8 | F9: =E9/$E$126 -> 0.0066006601 | G9: 1385 | H9: =G9/$G$126 -> 0.015815557 | I9: 400 | J9: =SUM(I9/I126) -> 0.00701747 | K9: 16661 | L9: =SUM(K9/K126) -> 0.014747772 | M9: 12.450611 | N9: =SUM(M9/M126) -> 0.0072957218 | O9: =D9*$O$129 -> 4.5132914e+08 | P9: =ROUNDUP(O9,0) -> 451329140
B10: 4 | C10: Nogotirto | D10: =SUM((F10*$F$4)+(H10*$H$4)+($J$4*J10)+($L$4*L10)+($N$4*N10)) -> 0.0099837671 | E10: 8 | F10: =E10/$E$126 -> 0.0066006601 | G10: 1295 | H10: =G10/$G$126 -> 0.014787832 | I10: 349 | J10: =SUM(I10/I126) -> 0.0061227426 | K10: 18613 | L10: =SUM(K10/K126) -> 0.016475618 | M10: 8.9821654 | N10: =SUM(M10/M126) -> 0.0052633064 | O10: =D10*$O$129 -> 4.406411e+08 | P10: =ROUNDUP(O10,0) -> 440641099
B11: 5 | C11: Trihanggo | D11: =SUM((F11*$F$4)+(H11*$H$4)+($J$4*J11)+($L$4*L11)+($N$4*N11)) -> 0.012441446 | E11: 12 | F11: =E11/$E$126 -> 0.0099009901 | G11: 1498 | H11: =G11/$G$126 -> 0.017105924 | I11: 562 | J11: =SUM(I11/I126) -> 0.0098595453 | K11: 18729 | L11: =SUM(K11/K126) -> 0.016578297 | M11: 13.010768 | N11: =SUM(M11/M126) -> 0.007623959 | O11: =D11*$O$129 -> 5.4911263e+08 | P11: =ROUNDUP(O11,0) -> 549112626
C12: JUMLAH | D12: =SUM(D7:D11) -> 0.062380923 | E12: =SUM(E7:E11) -> 59 | F12: =SUM(F7:F11) -> 0.048679868 | G12: =SUM(G7:G11) -> 7379 | H12: =SUM(H7:H11) -> 0.084262093 | I12: =SUM(I7:I11) -> 2907 | J12: =SUM(J7:J11) -> 0.050999463 | K12: =SUM(K7:K11) -> 97751 | ... P12: =SUM(P7:P11) -> 2753229131 | U12: =SUM(T7:T11) -> 0
B13: II. | C13: GODEAN
B14: 6 | C14: Sidorejo | D14: =SUM((F14*$F$4)+(H14*$H$4)+($J$4*J14)+($L$4*L14)+($N$4*N14)) -> 0.0097406697 | E14: 13 | F14: =E14/$E$126 -> 0.010726073 | G14: 886 | H14: =G14/$G$126 -> 0.010117389 | I14: 508 | J14: =SUM(I14/I126) -> 0.0089121869 | K14: 7091 | L14: =SUM(K14/K126) -> 0.006276721 | M14: 24.942933 | N14: =SUM(M14/M126) -> 0.014615885 | O14: =D14*$O$129 -> 4.2991181e+08 | P14: =ROUNDUP(O14,0) -> 429911810
B15: 7 | C15: Sidoluhur | D15: =SUM((F15*$F$4)+(H15*$H$4)+($J$4*J15)+($L$4*L15)+($N$4*N15)) -> 0.010806023 | E15: 15 | F15: =E15/$E$126 -> 0.012376238 | G15: 999 | H15: =G15/$G$126 -> 0.011407756 | I15: 489 | J15: =SUM(I15/I126) -> 0.0085788571 | K15: 10258 | L15: =SUM(K15/K126) -> 0.0090800457 | M15: 21.840941 | N15: =SUM(M15/M126) -> 0.012798201 | O15: =D15*$O$129 -> 4.7693199e+08 | P15: =ROUNDUP(O15,0) -> 476931989
B16: 8 | C16: Sidomulyo | D16: =SUM((F16*$F$4)+(H16*$H$4)+($J$4*J16)+($L$4*L16)+($N$4*N16)) -> 0.0067255449 | E16: 8 | F16: =E16/$E$126 -> 0.0066006601 | G16: 532 | H16: =G16/$G$126 -> 0.0060750011 | I16: 273.5 | J16: =SUM(I16/I126) -> 0.0047981951 | K16: 6614 | L16: =SUM(K16/K126) -> 0.0058544962 | M16: 23.888616 | N16: =SUM(M16/M126) -> 0.013998084 | O16: =D16*$O$129 -> 2.96837e+08 | P16: =ROUNDUP(O16,0) -> 296837003
B17: 9 | C17: Sidoagung | D17: =SUM((F17*$F$4)+(H17*$H$4)+($J$4*J17)+($L$4*L17)+($N$4*N17)) -> 0.0079817428 | E17: 8 | F17: =E17/$E$126 -> 0.0066006601 | G17: 908 | H17: =G17/$G$126 -> 0.010368611 | I17: 301.2 | J17: =SUM(I17/I126) -> 0.0052841549 | K17: 9802 | L17: =SUM(K17/K126) -> 0.0086764094 | M17: 19.381605 | N17: =SUM(M17/M126) -> 0.011357097 | O17: =D17*$O$129 -> 3.5228024e+08 | P17: =ROUNDUP(O17,0) -> 352280244
B18: 10 | C18: Sidokarto | D18: =SUM((F18*$F$4)+(H18*$H$4)+($J$4*J18)+($L$4*L18)+($N$4*N18)) -> 0.010702007 | E18: 14 | F18: =E18/$E$126 -> 0.011551155 | G18: 1259 | H18: =G18/$G$126 -> 0.014376741 | I18: 364 | J18: =SUM(I18/I126) -> 0.0063858977 | K18: 12525 | L18: =SUM(K18/K126) -> 0.01108672 | M18: 14.792298 | N18: =SUM(M18/M126) -> 0.008667887 | O18: =D18*$O$129 -> 4.7234116e+08 | P18: =ROUNDUP(O18,0) -> 472341159
B19: 11 | C19: Sidoarum | D19: =SUM((F19*$F$4)+(H19*$H$4)+($J$4*J19)+($L$4*L19)+($N$4*N19)) -> 0.010701473 | E19: 8 | F19: =E19/$E$126 -> 0.0066006601 | G19: 1516 | H19: =G19/$G$126 -> 0.017311469 | I19: 341.4 | J19: =SUM(I19/I126) -> 0.0059894106 | K19: 17421 | L19: =SUM(K19/K126) -> 0.015420499 | M19: 16.673118 | N19: =SUM(M19/M126) -> 0.0097699973 | O19: =D19*$O$129 -> 4.7231761e+08 | P19: =ROUNDUP(O19,0) -> 472317611
B20: 12 | C20: Sidomoyo | D20: =SUM((F20*$F$4)+(H20*$H$4)+($J$4*J20)+($L$4*L20)+($N$4*N20)) -> 0.0085469398 | E20: 11 | F20: =E20/$E$126 -> 0.0090759076 | G20: 770 | H20: =G20/$G$126 -> 0.0087927648 | I20: 275.5 | J20: =SUM(I20/I126) -> 0.0048332825 | K20: 9174 | L20: =SUM(K20/K126) -> 0.0081205244 | M20: 25.169304 | N20: =SUM(M20/M126) -> 0.014748532 | O20: =D20*$O$129 -> 3.7722564e+08 | P20: =ROUNDUP(O20,0) -> 377225642
C21: JUMLAH | D21: =SUM(D14:D20) -> 0.065204401 | E21: =SUM(E14:E20) -> 77 | F21: =SUM(F14:F20) -> 0.063531353 | G21: =SUM(G14:G20) -> 6870 | H21: =SUM(H14:H20) -> 0.078449733 | I21: =SUM(I14:I20) -> 2552.6 | J21: =SUM(J14:J20) -> 0.044781985 | K21: =SUM(K14:K20) -> 72885 | ... P21: =SUM(P14:P20) -> 2877845458
B22: III. | C22: MOYUDAN
B23: 13 | C23: Sumberrrahayu | D23: =SUM((F23*$F$4)+(H23*$H$4)+($J$4*J23)+($L$4*L23)+($N$4*N23)) -> 0.01004181 | E23: 15 | F23: =E23/$E$126 -> 0.012376238 | G23: 586 | H23: =G23/$G$126 -> 0.0066916366 | I23: 631 | J23: =SUM(I23/I126) -> 0.011070059 | K23: 6663 | L23: =SUM(K23/K126) -> 0.0058978694 | M23: 27.254248 | N23: =SUM(M23/M126) -> 0.015970253 | O23: =D23*$O$129 -> 4.4320285e+08 | P23: =ROUNDUP(O23,0) -> 443202847
B24: 14 | C24: Sumbersari | D24: =SUM((F24*$F$4)+(H24*$H$4)+($J$4*J24)+($L$4*L24)+($N$4*N24)) -> 0.009858692 | E24: 13 | F24: =E24/$E$126 -> 0.010726073 | G24: 793 | H24: =G24/$G$126 -> 0.0090554058 | I24: 546 | J24: =SUM(I24/I126) -> 0.0095788465 | K24: 8291 | L24: =SUM(K24/K126) -> 0.0073389217 | M24: 24.680922 | N24: =SUM(M24/M126) -> 0.014462354 | O24: =D24*$O$129 -> 4.3512081e+08 | P24: =ROUNDUP(O24,0) -> 435120813
B25: 15 | C25: Sumberagung | D25: =SUM((F25*$F$4)+(H25*$H$4)+($J$4*J25)+($L$4*L25)+($N$4*N25)) -> 0.013880821 | E25: 21 | F25: =E25/$E$126 -> 0.017326733 | G25: 1073 | H25: =G25/$G$126 -> 0.012252775 | I25: 820 | J25: =SUM(I25/I126) -> 0.014385813 | K25: 11855 | L25: =SUM(K25/K126) -> 0.010493658 | M25: 21.44044 | N25: =SUM(M25/M126) -> 0.012563519 | O25: =D25*$O$129 -> 612640508 | P25: =ROUNDUP(O25,0) -> 612640508
B26: 16 | C26: Sumberarum | D26: =SUM((F26*$F$4)+(H26*$H$4)+($J$4*J26)+($L$4*L26)+($N$4*N26)) -> 0.011054824 | E26: 16 | F26: =E26/$E$126 -> 0.01320132 | G26: 747 | H26: =G26/$G$126 -> 0.0085301238 | I26: 765 | J26: =SUM(I26/I126) -> 0.013420911 | K26: 7175 | L26: =SUM(K26/K126) -> 0.006351075 | M26: 24.472223 | N26: =SUM(M26/M126) -> 0.014340062 | O26: =D26*$O$129 -> 4.8791301e+08 | P26: =ROUNDUP(O26,0) -> 487913013
C27: JUMLAH | D27: =SUM(D23:D26) -> 0.044836147 | E27: =SUM(E23:E26) -> 65 | F27: =SUM(F23:F26) -> 0.053630363 | G27: =SUM(G23:G26) -> 3199 | H27: =SUM(H23:H26) -> 0.036529941 | I27: =SUM(I23:I26) -> 2762 | J27: =SUM(J23:J26) -> 0.04845563 | K27: =SUM(K23:K26) -> 33984 | ... P27: =SUM(P23:P26) -> 1978877181
B28: IV. | C28: MINGGIR
B29: 17 | C29: Sendangarum | D29: =SUM((F29*$F$4)+(H29*$H$4)+($J$4*J29)+($L$4*L29)+($N$4*N29)) -> 0.0056173347 | E29: 9 | F29: =E29/$E$126 -> 0.0074257426 | G29: 300 | H29: =G29/$G$126 -> 0.0034257525 | I29: 345 | J29: =SUM(I29/I126) -> 0.0060525679 | K29: 3635 | L29: =SUM(K29/K126) -> 0.003217583 | M29: 14.513147 | N29: =SUM(M29/M126) -> 0.0085043121 | O29: =D29*$O$129 -> 2.4792531e+08 | P29: =ROUNDUP(O29,0) -> 247925306
B30: 18 | C30: Sendangmulyo | D30: =SUM((F30*$F$4)+(H30*$H$4)+($J$4*J30)+($L$4*L30)+($N$4*N30)) -> 0.010810898 | E30: 16 | F30: =E30/$E$126 -> 0.01320132 | G30: 960 | H30: =G30/$G$126 -> 0.010962408 | I30: 670 | J30: =SUM(I30/I126) -> 0.011754262 | K30: 7025 | L30: =SUM(K30/K126) -> 0.0062182999 | M30: 18.149443 | N30: =SUM(M30/M126) -> 0.010635083 | O30: =D30*$O$129 -> 4.7714716e+08 | P30: =ROUNDUP(O30,0) -> 477147163
B31: 19 | C31: Sendangagung | D31: =SUM((F31*$F$4)+(H31*$H$4)+($J$4*J31)+($L$4*L31)+($N$4*N31)) -> 0.011377209 | E31: 15 | F31: =E31/$E$126 -> 0.012376238 | G31: 1150 | H31: =G31/$G$126 -> 0.013132051 | I31: 656 | J31: =SUM(I31/I126) -> 0.011508651 | K31: 8255 | L31: =SUM(K31/K126) -> 0.0073070557 | M31: 21.755039 | N31: =SUM(M31/M126) -> 0.012747866 | O31: =D31*$O$129 -> 5.0214172e+08 | P31: =ROUNDUP(O31,0) -> 502141725
B32: 20 | C32: Sendangsari | D32: =SUM((F32*$F$4)+(H32*$H$4)+($J$4*J32)+($L$4*L32)+($N$4*N32)) -> 0.0083830795 | E32: 12 | F32: =E32/$E$126 -> 0.0099009901 | G32: 640 | H32: =G32/$G$126 -> 0.0073082721 | I32: 458 | J32: =SUM(I32/I126) -> 0.0080350031 | K32: 5158 | L32: =SUM(K32/K126) -> 0.0045656927 | M32: 24.420731 | N32: =SUM(M32/M126) -> 0.014309889 | O32: =D32*$O$129 -> 3.6999354e+08 | P32: =ROUNDUP(O32,0) -> 369993542
B33: 21 | C33: Sendangrejo | D33: =SUM((F33*$F$4)+(H33*$H$4)+($J$4*J33)+($L$4*L33)+($N$4*N33)) -> 0.011292464 | E33: 16 | F33: =E33/$E$126 -> 0.01320132 | G33: 1046 | H33: =G33/$G$126 -> 0.011944457 | I33: 598 | J33: =SUM(I33/I126) -> 0.010491118 | K33: 8759 | L33: =SUM(K33/K126) -> 0.00775318 | M33: 22.08834 | N33: =SUM(M33/M126) -> 0.012943171 | O33: =D33*$O$129 -> 4.9840143e+08 | P33: =ROUNDUP(O33,0) -> 498401426
C34: JUMLAH | D34: =SUM(D29:D33) -> 0.047480986 | E34: =SUM(E29:E33) -> 68 | F34: =SUM(F29:F33) -> 0.056105611 | G34: =SUM(G29:G33) -> 4096 | H34: =SUM(H29:H33) -> 0.046772941 | I34: =SUM(I29:I33) -> 2727 | J34: =SUM(J29:J33) -> 0.047841602 | K34: =SUM(K29:K33) -> 32832 | ... P34: =SUM(P29:P33) -> 2095609162
B35: V. | C35: SEYEGAN
B36: 22 | C36: Margoluwih | D36: =SUM((F36*$F$4)+(H36*$H$4)+($J$4*J36)+($L$4*L36)+($N$4*N36)) -> 0.012121477 | E36: 14 | F36: =E36/$E$126 -> 0.011551155 | G36: 1568 | H36: =G36/$G$126 -> 0.017905267 | I36: 500 | J36: =SUM(I36/I126) -> 0.0087718375 | K36: 11292 | L36: =SUM(K36/K126) -> 0.0099953086 | M36: 22.554765 | N36: =SUM(M36/M126) -> 0.013216483 | O36: =D36*$O$129 -> 5.3499055e+08 | P36: =ROUNDUP(O36,0) -> 534990555
B37: 23 | C37: Margodadi | D37: =SUM((F37*$F$4)+(H37*$H$4)+($J$4*J37)+($L$4*L37)+($N$4*N37)) -> 0.011603802 | E37: 16 | F37: =E37/$E$126 -> 0.01320132 | G37: 1140 | H37: =G37/$G$126 -> 0.01301786 | I37: 611 | J37: =SUM(I37/I126) -> 0.010719185 | K37: 9637 | L37: =SUM(K37/K126) -> 0.0085303568 | M37: 20.306838 | N37: =SUM(M37/M126) -> 0.011899259 | O37: =D37*$O$129 -> 5.1214257e+08 | P37: =ROUNDUP(O37,0) -> 512142572
B38: 24 | C38: Margokaton | D38: =SUM((F38*$F$4)+(H38*$H$4)+($J$4*J38)+($L$4*L38)+($N$4*N38)) -> 0.0096998507 | E38: 12 | F38: =E38/$E$126 -> 0.0099009901 | G38: 891 | H38: =G38/$G$126 -> 0.010174485 | I38: 515 | J38: =SUM(I38/I126) -> 0.0090349926 | K38: 8098 | L38: =SUM(K38/K126) -> 0.0071680844 | M38: 24.814135 | N38: =SUM(M38/M126) -> 0.014540413 | O38: =D38*$O$129 -> 4.2811023e+08 | P38: =ROUNDUP(O38,0) -> 428110234
B39: 25 | C39: Margomulyo | D39: =SUM((F39*$F$4)+(H39*$H$4)+($J$4*J39)+($L$4*L39)+($N$4*N39)) -> 0.012515948 | E39: 13 | F39: =E39/$E$126 -> 0.010726073 | G39: 1675 | H39: =G39/$G$126 -> 0.019127118 | I39: 519 | J39: =SUM(I39/I126) -> 0.0091051673 | K39: 13538 | L39: =SUM(K39/K126) -> 0.011983394 | M39: 21.417207 | N39: =SUM(M39/M126) -> 0.012549905 | O39: =D39*$O$129 -> 5.5240082e+08 | P39: =ROUNDUP(O39,0) -> 552400824
B40: 26 | C40: Margoagung | D40: =SUM((F40*$F$4)+(H40*$H$4)+($J$4*J40)+($L$4*L40)+($N$4*N40)) -> 0.011525763 | E40: 12 | F40: =E40/$E$126 -> 0.0099009901 | G40: 1502 | H40: =G40/$G$126 -> 0.017151601 | I40: 518 | J40: =SUM(I40/I126) -> 0.0090876236 | K40: 10795 | L40: =SUM(K40/K126) -> 0.0095553805 | M40: 23.832923 | N40: =SUM(M40/M126) -> 0.01396545 | O40: =D40*$O$129 -> 5.0869825e+08 | P40: =ROUNDUP(O40,0) -> 508698251
C41: JUMLAH | D41: =SUM(D36:D40) -> 0.057466842 | E41: =SUM(E36:E40) -> 67 | F41: =SUM(F36:F40) -> 0.055280528 | G41: =SUM(G36:G40) -> 6776 | H41: =SUM(H36:H40) -> 0.07737633 | I41: =SUM(I36:I40) -> 2663 | J41: =SUM(J36:J40) -> 0.046718806 | K41: =SUM(K36:K40) -> 53360 | ... P41: =SUM(P36:P40) -> 2536342436
...

Sheet rekap hitungan
B1: Lampiran III
B2: Nomor Surat:
B3: Tanggal:
B5: ESTIMASI BESARAN ADD TA 2026
B6: Asumsi:
B7: 1. | C7: ADD kewenangan merupakan sisa dari pagu dikurangi alokasi earmark (siltap, BPJS Kes, BPJS naker, kebijakan, tunjangan BPKal) tanpa memperhitungkan keseimbangan proporsi belanja apbkal 30:70
B9: 2. | C9: Besaran tunjangan kedudukan BPKal:
C10: Ketua | D10: 2000000
C11: Wakil Ketua | D11: 1950000
C12: Sekretaris | D12: 1900000
C13: Kepala Bidang | D13: 1850000
C14: Sekretaris | D14: 1800000
B16: NO | C16: KAPANEWON/KALURAHAN | D16: ALOKASI DANA DESA
D17: (Rp)
D18: PENGHASILAN TETAP | E18: BPJS KESEHATAN (PEMBULATAN) | F18: BPJS KETENAGAKERJAAN (PEMBULATAN) | G18: KEBIJAKAN | H18: KEWENANGAN | K18: JUMLAH
H20: TUNJANGAN BPKal | I20: KEGIATAN | J20: JUMLAH
B21: 1 | C21: 2 | D21: 3 | E21: 4 | F21: 5 | G21: 6 | H21: 7 | I21: 8 | J21: 9=7+8 | K21: 10=3+4+5+6+9
B22: I. | C22: GAMPING
B23: 1. | C23: Balecatur | D23: ='hitung siltap'!M22 -> 933300000 | E23: =ROUND('hitung siltap'!P22,0) -> 10077696 | F23: =ROUND('hitung siltap'!W22,0) -> 73959126 | G23: ='hitung siltap'!X22 -> 155550000 | H23: 201000000 | I23: ='hitung kewenangan kegiatan'!P7 -> 689919442 | J23: =H23+I23 -> 890919442 | K23: =SUM(D23:G23)+J23 -> 2063806264
B24: 2. | C24: Ambarketawang | D24: ='hitung siltap'!M23 -> 759300000 | E24: =ROUND('hitung siltap'!P23,0) -> 10077696 | F24: =ROUND('hitung siltap'!W23,0) -> 63101526 | G24: ='hitung siltap'!X23 -> 126550000 | H24: 201000000 | I24: ='hitung kewenangan kegiatan'!P8 -> 622226824 | J24: =H24+I24 -> 823226824 | K24: =SUM(D24:G24)+J24 -> 1782256046
B25: 3. | C25: Banyuraden | D25: ='hitung siltap'!M24 -> 585300000 | E25: =ROUND('hitung siltap'!P24,0) -> 10077696 | F25: =ROUND('hitung siltap'!W24,0) -> 52243926 | G25: ='hitung siltap'!X24 -> 97550000 | H25: 201000000 | I25: ='hitung kewenangan kegiatan'!P9 -> 451329140 | J25: =H25+I25 -> 652329140 | K25: =SUM(D25:G25)+J25 -> 1397500762
B26: 4. | C26: Nogotirto | D26: ='hitung siltap'!M25 -> 585300000 | E26: =ROUND('hitung siltap'!P25,0) -> 10077696 | F26: =ROUND('hitung siltap'!W25,0) -> 52243926 | G26: ='hitung siltap'!X25 -> 97550000 | H26: 201000000 | I26: ='hitung kewenangan kegiatan'!P10 -> 440641099 | J26: =H26+I26 -> 641641099 | K26: =SUM(D26:G26)+J26 -> 1386812721
B27: 5. | C27: Trihanggo | D27: ='hitung siltap'!M26 -> 724500000 | E27: =ROUND('hitung siltap'!P26,0) -> 10077696 | F27: =ROUND('hitung siltap'!W26,0) -> 60930006 | G27: ='hitung siltap'!X26 -> 120750000 | H27: 201000000 | I27: ='hitung kewenangan kegiatan'!P11 -> 549112626 | J27: =H27+I27 -> 750112626 | K27: =SUM(D27:G27)+J27 -> 1666370328
B28: II. | C28: GODEAN
B29: 6. | C29: Sidorejo | D29: ='hitung siltap'!M28 -> 759300000 | E29: =ROUND('hitung siltap'!P28,0) -> 10077696 | F29: =ROUND('hitung siltap'!W28,0) -> 63101526 | G29: ='hitung siltap'!X28 -> 126550000 | H29: 157800000 | I29: ='hitung kewenangan kegiatan'!P14 -> 429911810 | J29: =H29+I29 -> 587711810 | K29: =SUM(D29:G29)+J29 -> 1546741032
B30: 7. | C30: Sidoluhur | D30: ='hitung siltap'!M29 -> 828900000 | E30: =ROUND('hitung siltap'!P29,0) -> 10077696 | F30: =ROUND('hitung siltap'!W29,0) -> 67444566 | G30: ='hitung siltap'!X29 -> 138150000 | H30: 201000000 | I30: ='hitung kewenangan kegiatan'!P15 -> 476931989 | J30: =H30+I30 -> 677931989 | K30: =SUM(D30:G30)+J30 -> 1722504251
B31: 8. | C31: Sidomulyo | D31: ='hitung siltap'!M30 -> 585300000 | E31: =ROUND('hitung siltap'!P30,0) -> 10077696 | F31: =ROUND('hitung siltap'!W30,0) -> 52243926 | G31: ='hitung siltap'!X30 -> 97550000 | H31: 157800000 | I31: ='hitung kewenangan kegiatan'!P16 -> 296837003 | J31: =H31+I31 -> 454637003 | K31: =SUM(D31:G31)+J31 -> 1199808625
B32: 9. | C32: Sidoagung | D32: ='hitung siltap'!M31 -> 585300000 | E32: =ROUND('hitung siltap'!P31,0) -> 10077696 | F32: =ROUND('hitung siltap'!W31,0) -> 52243926 | G32: ='hitung siltap'!X31 -> 97550000 | H32: 201000000 | I32: ='hitung kewenangan kegiatan'!P17 -> 352280244 | J32: =H32+I32 -> 553280244 | K32: =SUM(D32:G32)+J32 -> 1298451866
B33: 10. | C33: Sidokarto | D33: ='hitung siltap'!M32 -> 794100000 | E33: =ROUND('hitung siltap'!P32,0) -> 10077696 | F33: =ROUND('hitung siltap'!W32,0) -> 65273046 | G33: ='hitung siltap'!X32 -> 132350000 | H33: 201000000 | I33: ='hitung kewenangan kegiatan'!P18 -> 472341159 | J33: =H33+I33 -> 673341159 | K33: =SUM(D33:G33)+J33 -> 1675141901
B34: 11. | C34: Sidoarum | D34: ='hitung siltap'!M33 -> 585300000 | E34: =ROUND('hitung siltap'!P33,0) -> 10077696 | F34: =ROUND('hitung siltap'!W33,0) -> 52243926 | G34: ='hitung siltap'!X33 -> 97550000 | H34: 201000000 | I34: ='hitung kewenangan kegiatan'!P19 -> 472317611 | J34: =H34+I34 -> 673317611 | K34: =SUM(D34:G34)+J34 -> 1418489233
B35: 12. | C35: Sidomoyo | D35: ='hitung siltap'!M34 -> 689700000 | E35: =ROUND('hitung siltap'!P34,0) -> 10077696 | F35: =ROUND('hitung siltap'!W34,0) -> 58758486 | G35: ='hitung siltap'!X34 -> 114950000 | H35: 157800000 | I35: ='hitung kewenangan kegiatan'!P20 -> 377225642 | J35: =H35+I35 -> 535025642 | K35: =SUM(D35:G35)+J35 -> 1408511824
B36: III. | C36: MOYUDAN
B37: 13. | C37: Sumberrahayu | D37: ='hitung siltap'!M36 -> 828900000 | E37: =ROUND('hitung siltap'!P36,0) -> 10077696 | F37: =ROUND('hitung siltap'!W36,0) -> 67444566 | G37: ='hitung siltap'!X36 -> 138150000 | H37: 157800000 | I37: ='hitung kewenangan kegiatan'!P23 -> 443202847 | J37: =H37+I37 -> 601002847 | K37: =SUM(D37:G37)+J37 -> 1645575109
B38: 14. | C38: Sumbersari | D38: ='hitung siltap'!M37 -> 759300000 | E38: =ROUND('hitung siltap'!P37,0) -> 10077696 | F38: =ROUND('hitung siltap'!W37,0) -> 63101526 | G38: ='hitung siltap'!X37 -> 126550000 | H38: 201000000 | I38: ='hitung kewenangan kegiatan'!P24 -> 435120813 | J38: =H38+I38 -> 636120813 | K38: =SUM(D38:G38)+J38 -> 1595150035
B39: 15. | C39: Sumberagung | D39: ='hitung siltap'!M38 -> 1037700000 | E39: =ROUND('hitung siltap'!P38,0) -> 10077696 | F39: =ROUND('hitung siltap'!W38,0) -> 80473686 | G39: ='hitung siltap'!X38 -> 172950000 | H39: 201000000 | I39: ='hitung kewenangan kegiatan'!P25 -> 612640508 | J39: =H39+I39 -> 813640508 | K39: =SUM(D39:G39)+J39 -> 2114841890
B40: 16. | C40: Sumberarum | D40: ='hitung siltap'!M39 -> 863700000 | E40: =ROUND('hitung siltap'!P39,0) -> 10077696 | F40: =ROUND('hitung siltap'!W39,0) -> 69616086 | G40: ='hitung siltap'!X39 -> 143950000 | H40: 157800000 | I40: ='hitung kewenangan kegiatan'!P26 -> 487913013 | J40: =H40+I40 -> 645713013 | K40: =SUM(D40:G40)+J40 -> 1733056795
B41: IV. | C41: MINGGIR
B42: 17. | C42: Sendangarum | D42: ='hitung siltap'!M41 -> 620100000 | E42: =ROUND('hitung siltap'!P41,0) -> 10077696 | F42: =ROUND('hitung siltap'!W41,0) -> 54415446 | G42: ='hitung siltap'!X41 -> 103350000 | H42: 114600000 | I42: ='hitung kewenangan kegiatan'!P29 -> 247925306 | J42: =H42+I42 -> 362525306 | K42: =SUM(D42:G42)+J42 -> 1150468448
B43: 18. | C43: Sendangmulyo | D43: ='hitung siltap'!M42 -> 863700000 | E43: =ROUND('hitung siltap'!P42,0) -> 10077696 | F43: =ROUND('hitung siltap'!W42,0) -> 69616086 | G43: ='hitung siltap'!X42 -> 143950000 | H43: 157800000 | I43: ='hitung kewenangan kegiatan'!P30 -> 477147163 | J43: =H43+I43 -> 634947163 | K43: =SUM(D43:G43)+J43 -> 1722290945
B44: 19. | C44: Sendangagung | D44: ='hitung siltap'!M43 -> 828900000 | E44: =ROUND('hitung siltap'!P43,0) -> 10077696 | F44: =ROUND('hitung siltap'!W43,0) -> 67444566 | G44: ='hitung siltap'!X43 -> 138150000 | H44: 157800000 | I44: ='hitung kewenangan kegiatan'!P31 -> 502141725 | J44: =H44+I44 -> 659941725 | K44: =SUM(D44:G44)+J44 -> 1704513987
...

Sheet lamp. sk
A5: BESARAN ALOKASI DANA DESA TAHUN ANGGARAN 2026
A7: NO | B7: KAPANEWON/ | C7: ALOKASI DANA DESA
C8: (Rp)
B9: KALURAHAN | C9: PENGHASILAN TETAP | D9: BPJS KESEHATAN | E9: BPJS KETENAGAKERJAAN | F9: KEBIJAKAN | G9: KEWENANGAN | H9: JUMLAH
A11: 1 | B11: 2 | C11: 3 | D11: 4 | E11: 5 | F11: 6 | G11: 7 | H11: 8
A12: I. | B12: GAMPING
A13: 1. | B13: Balecatur | C13: ='rekap hitungan'!D23 -> 933300000 | D13: ='rekap hitungan'!E23 -> 10077696 | E13: ='rekap hitungan'!F23 -> 73959126 | F13: ='rekap hitungan'!G23 -> 155550000 | G13: ='rekap hitungan'!J23 -> 890919442 | H13: =SUM(C13:G13) -> 2063806264
A14: 2. | B14: Ambarketawang | C14: ='rekap hitungan'!D24 -> 759300000 | D14: ='rekap hitungan'!E24 -> 10077696 | E14: ='rekap hitungan'!F24 -> 63101526 | F14: ='rekap hitungan'!G24 -> 126550000 | G14: ='rekap hitungan'!J24 -> 823226824 | H14: =SUM(C14:G14) -> 1782256046
A15: 3. | B15: Banyuraden | C15: ='rekap hitungan'!D25 -> 585300000 | D15: ='rekap hitungan'!E25 -> 10077696 | E15: ='rekap hitungan'!F25 -> 52243926 | F15: ='rekap hitungan'!G25 -> 97550000 | G15: ='rekap hitungan'!J25 -> 652329140 | H15: =SUM(C15:G15) -> 1397500762
A16: 4. | B16: Nogotirto | C16: ='rekap hitungan'!D26 -> 585300000 | D16: ='rekap hitungan'!E26 -> 10077696 | E16: ='rekap hitungan'!F26 -> 52243926 | F16: ='rekap hitungan'!G26 -> 97550000 | G16: ='rekap hitungan'!J26 -> 641641099 | H16: =SUM(C16:G16) -> 1386812721
A17: 5. | B17: Trihanggo | C17: ='rekap hitungan'!D27 -> 724500000 | D17: ='rekap hitungan'!E27 -> 10077696 | E17: ='rekap hitungan'!F27 -> 60930006 | F17: ='rekap hitungan'!G27 -> 120750000 | G17: ='rekap hitungan'!J27 -> 750112626 | H17: =SUM(C17:G17) -> 1666370328
A18: II. | B18: GODEAN
A19: 6. | B19: Sidorejo | C19: ='rekap hitungan'!D29 -> 759300000 | D19: ='rekap hitungan'!E29 -> 10077696 | E19: ='rekap hitungan'!F29 -> 63101526 | F19: ='rekap hitungan'!G29 -> 126550000 | G19: ='rekap hitungan'!J29 -> 587711810 | H19: =SUM(C19:G19) -> 1546741032
A20: 7. | B20: Sidoluhur | C20: ='rekap hitungan'!D30 -> 828900000 | D20: ='rekap hitungan'!E30 -> 10077696 | E20: ='rekap hitungan'!F30 -> 67444566 | F20: ='rekap hitungan'!G30 -> 138150000 | G20: ='rekap hitungan'!J30 -> 677931989 | H20: =SUM(C20:G20) -> 1722504251
A21: 8. | B21: Sidomulyo | C21: ='rekap hitungan'!D31 -> 585300000 | D21: ='rekap hitungan'!E31 -> 10077696 | E21: ='rekap hitungan'!F31 -> 52243926 | F21: ='rekap hitungan'!G31 -> 97550000 | G21: ='rekap hitungan'!J31 -> 454637003 | H21: =SUM(C21:G21) -> 1199808625
A22: 9. | B22: Sidoagung | C22: ='rekap hitungan'!D32 -> 585300000 | D22: ='rekap hitungan'!E32 -> 10077696 | E22: ='rekap hitungan'!F32 -> 52243926 | F22: ='rekap hitungan'!G32 -> 97550000 | G22: ='rekap hitungan'!J32 -> 553280244 | H22: =SUM(C22:G22) -> 1298451866
A23: 10. | B23: Sidokarto | C23: ='rekap hitungan'!D33 -> 794100000 | D23: ='rekap hitungan'!E33 -> 10077696 | E23: ='rekap hitungan'!F33 -> 65273046 | F23: ='rekap hitungan'!G33 -> 132350000 | G23: ='rekap hitungan'!J33 -> 673341159 | H23: =SUM(C23:G23) -> 1675141901
A24: 11. | B24: Sidoarum | C24: ='rekap hitungan'!D34 -> 585300000 | D24: ='rekap hitungan'!E34 -> 10077696 | E24: ='rekap hitungan'!F34 -> 52243926 | F24: ='rekap hitungan'!G34 -> 97550000 | G24: ='rekap hitungan'!J34 -> 673317611 | H24: =SUM(C24:G24) -> 1418489233
A25: 12. | B25: Sidomoyo | C25: ='rekap hitungan'!D35 -> 689700000 | D25: ='rekap hitungan'!E35 -> 10077696 | E25: ='rekap hitungan'!F35 -> 58758486 | F25: ='rekap hitungan'!G35 -> 114950000 | G25: ='rekap hitungan'!J35 -> 535025642 | H25: =SUM(C25:G25) -> 1408511824
A26: III. | B26: MOYUDAN
A27: 1 | B27: 2 | C27: 3 | D27: 4 | E27: 5 | F27: 6 | G27: 7 | H27: 8
A28: 13. | B28: Sumberrahayu | C28: ='rekap hitungan'!D37 -> 828900000 | D28: ='rekap hitungan'!E37 -> 10077696 | E28: ='rekap hitungan'!F37 -> 67444566 | F28: ='rekap hitungan'!G37 -> 138150000 | G28: ='rekap hitungan'!J37 -> 601002847 | H28: =SUM(C28:G28) -> 1645575109
A29: 14. | B29: Sumbersari | C29: ='rekap hitungan'!D38 -> 759300000 | D29: ='rekap hitungan'!E38 -> 10077696 | E29: ='rekap hitungan'!F38 -> 63101526 | F29: ='rekap hitungan'!G38 -> 126550000 | G29: ='rekap hitungan'!J38 -> 636120813 | H29: =SUM(C29:G29) -> 1595150035
A30: 15. | B30: Sumberagung | C30: ='rekap hitungan'!D39 -> 1037700000 | D30: ='rekap hitungan'!E39 -> 10077696 | E30: ='rekap hitungan'!F39 -> 80473686 | F30: ='rekap hitungan'!G39 -> 172950000 | G30: ='rekap hitungan'!J39 -> 813640508 | H30: =SUM(C30:G30) -> 2114841890
A31: 16. | B31: Sumberarum | C31: ='rekap hitungan'!D40 -> 863700000 | D31: ='rekap hitungan'!E40 -> 10077696 | E31: ='rekap hitungan'!F40 -> 69616086 | F31: ='rekap hitungan'!G40 -> 143950000 | G31: ='rekap hitungan'!J40 -> 645713013 | H31: =SUM(C31:G31) -> 1733056795
A32: IV. | B32: MINGGIR
A33: 17. | B33: Sendangarum | C33: ='rekap hitungan'!D42 -> 620100000 | D33: ='rekap hitungan'!E42 -> 10077696 | E33: ='rekap hitungan'!F42 -> 54415446 | F33: ='rekap hitungan'!G42 -> 103350000 | G33: ='rekap hitungan'!J42 -> 362525306 | H33: =SUM(C33:G33) -> 1150468448
A34: 18. | B34: Sendangmulyo | C34: ='rekap hitungan'!D43 -> 863700000 | D34: ='rekap hitungan'!E43 -> 10077696 | E34: ='rekap hitungan'!F43 -> 69616086 | F34: ='rekap hitungan'!G43 -> 143950000 | G34: ='rekap hitungan'!J43 -> 634947163 | H34: =SUM(C34:G34) -> 1722290945
A35: 19. | B35: Sendangagung | C35: ='rekap hitungan'!D44 -> 828900000 | D35: ='rekap hitungan'!E44 -> 10077696 | E35: ='rekap hitungan'!F44 -> 67444566 | F35: ='rekap hitungan'!G44 -> 138150000 | G35: ='rekap hitungan'!J44 -> 659941725 | H35: =SUM(C35:G35) -> 1704513987
A36: 20. | B36: Sendangsari | C36: ='rekap hitungan'!D45 -> 724500000 | D36: ='rekap hitungan'!E45 -> 10077696 | E36: ='rekap hitungan'!F45 -> 60930006 | F36: ='rekap hitungan'!G45 -> 120750000 | G36: ='rekap hitungan'!J45 -> 527793542 | H36: =SUM(C36:G36) -> 1444051244
A37: 21. | B37: Sendangrejo | C37: ='rekap hitungan'!D46 -> 863700000 | D37: ='rekap hitungan'!E46 -> 10077696 | E37: ='rekap hitungan'!F46 -> 69616086 | F37: ='rekap hitungan'!G46 -> 143950000 | G37: ='rekap hitungan'!J46 -> 699401426 | H37: =SUM(C37:G37) -> 1786745208
A38: V. | B38: SEYEGAN
A39: 22. | B39: Margoluwih | C39: ='rekap hitungan'!D48 -> 794100000 | D39: ='rekap hitungan'!E48 -> 10077696 | E39: ='rekap hitungan'!F48 -> 65273046 | F39: ='rekap hitungan'!G48 -> 132350000 | G39: ='rekap hitungan'!J48 -> 735990555 | H39: =SUM(C39:G39) -> 1737791297
A40: 23. | B40: Margodadi | C40: ='rekap hitungan'!D49 -> 863700000 | D40: ='rekap hitungan'!E49 -> 10077696 | E40: ='rekap hitungan'!F49 -> 69616086 | F40: ='rekap hitungan'!G49 -> 143950000 | G40: ='rekap hitungan'!J49 -> 713142572 | H40: =SUM(C40:G40) -> 1800486354
A41: 24. | B41: Margokaton | C41: ='rekap hitungan'!D50 -> 724500000 | D41: ='rekap hitungan'!E50 -> 10077696 | E41: ='rekap hitungan'!F50 -> 60930006 | F41: ='rekap hitungan'!G50 -> 120750000 | G41: ='rekap hitungan'!J50 -> 585910234 | H41: =SUM(C41:G41) -> 1502167936
A42: 25. | B42: Margomulyo | C42: ='rekap hitungan'!D51 -> 759300000 | D42: ='rekap hitungan'!E51 -> 10077696 | E42: ='rekap hitungan'!F51 -> 63101526 | F42: ='rekap hitungan'!G51 -> 126550000 | G42: ='rekap hitungan'!J51 -> 753400824 | H42: =SUM(C42:G42) -> 1712430046
A43: 26. | B43: Margoagung | C43: ='rekap hitungan'!D52 -> 724500000 | D43: ='rekap hitungan'!E52 -> 10077696 | E43: ='rekap hitungan'!F52 -> 60930006 | F43: ='rekap hitungan'!G52 -> 120750000 | G43: ='rekap hitungan'!J52 -> 709698251 | H43: =SUM(C43:G43) -> 1625955953
A44: VI. | B44: MLATI
A45: 27. | B45: Sinduadi | C45: ='rekap hitungan'!D54 -> 933300000 | D45: ='rekap hitungan'!E54 -> 10077696 | E45: ='rekap hitungan'!F54 -> 73959126 | F45: ='rekap hitungan'!G54 -> 155550000 | G45: ='rekap hitungan'!J54 -> 1046577985 | H45: =SUM(C45:G45) -> 2219464807
A46: 28. | B46: Sendangadi | C46: ='rekap hitungan'!D55 -> 794100000 | D46: ='rekap hitungan'!E55 -> 10077696 | E46: ='rekap hitungan'!F55 -> 65273046 | F46: ='rekap hitungan'!G55 -> 132350000 | G46: ='rekap hitungan'!J55 -> 765253089 | H46: =SUM(C46:G46) -> 1767053831
...

Sheet hitung premi dpa pmk
B1: Lampiran IV
B2: Nomor Surat:
B3: Tanggal:
B5: PERHITUNGAN BESARAN PREMI BPJS KESEHATAN LURAH DAN PAMONG KALURAHAN
B6: DENGAN KENAIKAN SILTAP 8%
B8: NO | C8: URAIAN | D8: JUMLAH ORANG | E8: SILTAP PER BULAN | F8: PREMI PER BULAN | H8: JUMLAH PREMI PER TAHUN
F9: 0.04 | G9: Rp
B10: 1 | C10: 2 | D10: 3 | E10: 4 | F10: 5=4x4% | G10: 6=3x5 | H10: 7=6x12 bln
B11: 1 | C11: Lurah | D11: 86 | E11: ='hitung siltap'!H11 -> 4275000 | F11: =4%*E11 -> 171000 | G11: =D11*F11 -> 14706000 | H11: =G11*12 -> 176472000
B12: 2 | C12: Carik | D12: 86 | E12: ='hitung siltap'!H12 -> 3300000 | F12: =4%*E12 -> 132000 | G12: =D12*F12 -> 11352000 | H12: =G12*12 -> 136224000
B13: 3 | C13: Kaur & Kasi | D13: =6*86 -> 516 | E13: ='hitung siltap'!H13 -> 3000000 | F13: =4%*E13 -> 120000 | G13: =D13*F13 -> 61920000 | H13: =G13*12 -> 743040000
B14: 4 | C14: Dukuh | D14: 1212 | E14: ='hitung siltap'!H14 -> 2900000 | F14: =4%*E14 -> 116000 | G14: =D14*F14 -> 140592000 | H14: =G14*12 -> 1687104000
C15: JUMLAH TOTAL | D15: =SUM(D11:D14) -> 1900 | F15: =SUM(F11:F14) -> 539000 | G15: =SUM(G11:G14) -> 228570000 | H15: =SUM(H11:H14) -> 2742840000
D17: BELANJA PREMI KESEHATAN 2025 MURNI | H17: 2032240195
D18: ESTIMASI BELANJA PREMI KESEHATAN TA 2026 | H18: =H15 -> 2742840000
D19: PERLU TAMBAHAN | H19: =H18-H17 -> 710599805

Sheet checklist add & premi 26
B2: Lampiran
B3: Nomor Surat:
B4: Tanggal:
B6: ESTIMASI KEBUTUHAN ANGGARAN ADD TA 2026
B8: NO | C8: URAIAN | D8: ADD MURNI 2025 | E8: ESTIMASI 2026
G9: selisih
B10: 1 | C10: 2 | D10: 3 | E10: 6
B11: 1 | C11: ADD Siltap | D11: 54295200000 | E11: ='lamp. sk'!C120 -> 68571000000
B12: 2 | C12: ADD BPJS Kesehatan (Staf) | D12: 814541948 | E12: ='lamp. sk'!D120 -> 866681856
B13: 3 | C13: ADD BPJS Naker (Lurah, Pamong, Staf) | D13: 4867874149 | E13: ='lamp. sk'!E120 -> 5630854116
B14: 4 | C14: ADD Kebijakan | D14: 9049200000 | E14: ='lamp. sk'!F120 -> 11428500000
B15: 5 | C15: ADD Kewenangan: | D15: 54943374853
C16: tunjangan BPKal | D16: 0 | E16: ='rekap hitungan'!H125 -> 15774000000
C17: kegiatan | E17: ='rekap hitungan'!I125 -> 44135754834
C18: JUMLAH ADD | D18: =SUM(D11:D17) -> 123970190950 | E18: =SUM(E11:E17) -> 146406790806 | G18: =E18-D18 -> 22436599856

Sheet perbandingan
B1: Lampiran III
B2: Nomor Surat:
B3: Tanggal:
B5: PERBANDINGAN BESARAN ADD KEWENANGAN KEGIATAN
B7: NO. | C7: KAPANEWON/KALURAHAN | D7: ADD KEWENANGAN KEGIATAN | H7: ESTIMASI BESARAN TUNJANGAN BPKal YANG SELAMA INI DIALOKASIKAN DALAM APBKal | I7: DENGAN KONSEP TUNJANGAN BPKal DI-COVER DALAM ADD KEWENANGAN MAKA SELISIH RIIL SETELAH DIPERHITUNGKAN ADALAH | L7: KONDISI PAD PADA LPJ 2024
D11: APBD TA 2025 | E11: SIMULASI HITUNGAN 2026 | F11: SELISIH
F12: Rp | G12: % | I12: Rp | J12: % | K12: DI ATAS 10% DIJUSTIFIKASI TERDAPAT PENGARUH CUKUP SIGNIFIKAN TERHADAP KONDISI KEUANGAN
B13: 1 | C13: 2 | D13: 3 | E13: 4 | F13: 5=3-4 | G13: 6=5/3x100% | H13: 7 | I13: 8=5-7 | J13: 9=8/3x100% | K13: 10 | L13: 11
B14: I. | C14: GAMPING
B15: 1. | C15: Balecatur | D15: 852412055 | E15: 641642141 | F15: =D15-E15 -> 210769914 | G15: =F15/D15*100 -> 24.726294 | H15: 103800000 | I15: =F15-H15 -> 106969914 | J15: =I15/D15*100 -> 12.549085 | K15: * | L15: 459,366,091.00
B16: 2. | C16: Ambarketawang | D16: 767131353 | E16: 577448197 | F16: =D16-E16 -> 189683156 | G16: =F16/D16*100 -> 24.726294 | H16: 120000000 | I16: =F16-H16 -> 69683156 | J16: =I16/D16*100 -> 9.0836016 | L16: 536,535,308.00
B17: 3. | C17: Banyuraden | D17: 569252290 | E17: 428497293 | F17: =D17-E17 -> 140754997 | G17: =F17/D17*100 -> 24.726294 | H17: 114600000 | I17: =F17-H17 -> 26154997 | J17: =I17/D17*100 -> 4.5946231 | L17: 1,134,871,240.00
B18: 4. | C18: Nogotirto | D18: 538211700 | E18: 405131891 | F18: =D18-E18 -> 133079809 | G18: =F18/D18*100 -> 24.726294 | H18: 109200000 | I18: =F18-H18 -> 23879809 | J18: =I18/D18*100 -> 4.4368803 | L18: 53,654,870.00
B19: 5. | C19: Trihanggo | D19: 686345486 | E19: 516637681 | F19: =D19-E19 -> 169707805 | G19: =F19/D19*100 -> 24.726294 | H19: 147000000 | I19: =F19-H19 -> 22707805 | J19: =I19/D19*100 -> 3.3085094 | L19: 253,678,698.00
B20: II. | C20: GODEAN
B21: 6. | C21: Sidorejo | D21: 536319322 | E21: 403707428 | F21: =D21-E21 -> 132611894 | G21: =F21/D21*100 -> 24.726294 | H21: 65400000 | I21: =F21-H21 -> 67211894 | J21: =I21/D21*100 -> 12.532066 | K21: * | L21: 35,861,550.00
B22: 7. | C22: Sidoluhur | D22: 588894473 | E22: 443282692 | F22: =D22-E22 -> 145611781 | G22: =F22/D22*100 -> 24.726294 | H22: 114600000 | I22: =F22-H22 -> 31011781 | J22: =I22/D22*100 -> 5.2661016 | L22: 786,423,258.00
B23: 8. | C23: Sidomulyo | D23: 377192820 | E23: 283927013 | F23: =D23-E23 -> 93265807 | G23: =F23/D23*100 -> 24.726294 | H23: 65400000 | I23: =F23-H23 -> 27865807 | J23: =I23/D23*100 -> 7.3876822 | L23: 45,348,800.00
B24: 9. | C24: Sidoagung | D24: 434838082 | E24: 327318738 | F24: =D24-E24 -> 107519344 | G24: =F24/D24*100 -> 24.726294 | H24: 103800000 | I24: =F24-H24 -> 3719344 | J24: =I24/D24*100 -> 0.85533999 | L24: 118,514,000.00
B25: 10. | C25: Sidokarto | D25: 592335647 | E25: 445872991 | F25: =D25-E25 -> 146462656 | G25: =F25/D25*100 -> 24.726294 | H25: 87600000 | I25: =F25-H25 -> 58862656 | J25: =I25/D25*100 -> 9.937382 | L25: 335,396,894.00
B26: 11. | C26: Sidoarum | D26: 584194557 | E26: 439744891 | F26: =D26-E26 -> 144449666 | G26: =F26/D26*100 -> 24.726294 | H26: 93000000 | I26: =F26-H26 -> 51449666 | J26: =I26/D26*100 -> 8.8069403 | L26: 164,792,000.00
B27: 12. | C27: Sidomoyo | D27: 470136077 | E27: 353888847 | F27: =D27-E27 -> 116247230 | G27: =F27/D27*100 -> 24.726294 | H27: 78000000 | I27: =F27-H27 -> 38247230 | J27: =I27/D27*100 -> 8.1353531 | L27: 56,370,250.00
B28: III. | C28: MOYUDAN
B29: 13. | C29: Sumberrahayu | D29: 556507176 | E29: 418903574 | F29: =D29-E29 -> 137603602 | G29: =F29/D29*100 -> 24.726294 | H29: 78000000 | I29: =F29-H29 -> 59603602 | J29: =I29/D29*100 -> 10.710302 | K29: * | L29: 129,724,116.00
B30: 14. | C30: Sumbersari | D30: 543740023 | E30: 409293264 | F30: =D30-E30 -> 134446759 | G30: =F30/D30*100 -> 24.726294 | H30: 93000000 | I30: =F30-H30 -> 41446759 | J30: =I30/D30*100 -> 7.6225323 | L30: 141,794,396.00
B31: 15. | C31: Sumberagung | D31: 760636022 | E31: 572558920 | F31: =D31-E31 -> 188077102 | G31: =F31/D31*100 -> 24.726294 | H31: 103800000 | I31: =F31-H31 -> 84277102 | J31: =I31/D31*100 -> 11.07982 | K31: * | L31: 143,151,184.25
B32: 16. | C32: Sumberarum | D32: 608412879 | E32: 457974919 | F32: =D32-E32 -> 150437960 | G32: =F32/D32*100 -> 24.726294 | H32: 73800000 | I32: =F32-H32 -> 76637960 | J32: =I32/D32*100 -> 12.596374 | K32: * | L32: 175,842,951.00
B33: IV. | C33: MINGGIR
B34: 17. | C34: Sendangarum | D34: 306512924 | E34: 230723636 | F34: =D34-E34 -> 75789288 | G34: =F34/D34*100 -> 24.726294 | H34: 60600000 | I34: =F34-H34 -> 15189288 | J34: =I34/D34*100 -> 4.9555131 | L34: 215,928,434.00
B35: 18. | C35: Sendangmulyo | D35: 598833272 | E35: 450763994 | F35: =D35-E35 -> 148069278 | G35: =F35/D35*100 -> 24.726294 | H35: 99000000 | I35: =F35-H35 -> 49069278 | J35: =I35/D35*100 -> 8.1941469 | L35: 77,235,599.00
B36: 19. | C36: Sendangagung | D36: 617993920 | E36: 465186924 | F36: =D36-E36 -> 152806996 | G36: =F36/D36*100 -> 24.726294 | H36: 86400000 | I36: =F36-H36 -> 66406996 | J36: =I36/D36*100 -> 10.745574 | K36: * | L36: 66,734,849.00
B37: 20. | C37: Sendangsari | D37: 458083227 | E37: 344816220 | F37: =D37-E37 -> 113267007 | G37: =F37/D37*100 -> 24.726294 | H37: 90600000 | I37: =F37-H37 -> 22667007 | J37: =I37/D37*100 -> 4.948229 | L37: 175,248,374.00
B38: 21. | C38: Sendangrejo | D38: 623097074 | E38: 469028257 | F38: =D38-E38 -> 154068817 | G38: =F38/D38*100 -> 24.726294 | H38: 103800000 | I38: =F38-H38 -> 50268817 | J38: =I38/D38*100 -> 8.0675739 | L38: 95,708,500.00
B39: V. | C39: SEYEGAN
B40: 22. | C40: Margoluwih | D40: 668406672 | E40: 503134471 | F40: =D40-E40 -> 165272201 | G40: =F40/D40*100 -> 24.726294 | H40: 109200000 | I40: =F40-H40 -> 56072201 | J40: =I40/D40*100 -> 8.388935 | L40: 93,251,000.00
B41: 23. | C41: Margodadi | D41: 639482302 | E41: 481362026 | F41: =D41-E41 -> 158120276 | G41: =F41/D41*100 -> 24.726294 | H41: 103800000 | I41: =F41-H41 -> 54320276 | J41: =I41/D41*100 -> 8.4944143 | L41: 93,565,729.00
B42: 24. | C42: Margokaton | D42: 530490879 | E42: 399320142 | F42: =D42-E42 -> 131170737 | G42: =F42/D42*100 -> 24.726294 | H42: 82200000 | I42: =F42-H42 -> 48970737 | J42: =I42/D42*100 -> 9.2312119 | L42: 123,997,000.00
B43: 25. | C43: Margomulyo | D43: 688339038 | E43: 518138301 | F43: =D43-E43 -> 170200737 | G43: =F43/D43*100 -> 24.726294 | H43: 103800000 | I43: =F43-H43 -> 66400737 | J43: =I43/D43*100 -> 9.6465162 | L43: 183,996,900.00
B44: 26. | C44: Margoagung | D44: 635174829 | E44: 478119631 | F44: =D44-E44 -> 157055198 | G44: =F44/D44*100 -> 24.726294 | H44: 109200000 | I44: =F44-H44 -> 47855198 | J44: =I44/D44*100 -> 7.5341773 | L44: 116,059,000.00
B45: VI. | C45: MLATI
...

Sheet tren add
B1: ALOKASI DANA DESA
D3: 2022 | E3: 2023 | F3: selisih 2023 terhadap 2022 | G3: 2024 | H3: selisih 2024 terhadap 2023 | I3: 2025 murni | J3: selisih 2025 murni terhadap 2024 | K3: 2025 perubahan | L3: selisih 2025 perubahan terhadap 2024 | M3: 2026 | N3: selisih 2026 terhadap 2025 murni
B4: I. | C4: GAMPING
B5: 1. | C5: Balecatur | D5: 1.495007e+09 | E5: 1777257376 | F5: =E5-D5 -> 2.8225043e+08 | G5: 1786205335 | H5: =G5-E5 -> 8947959 | I5: 1.7867026e+09 | J5: =I5-G5 -> 497224.5 | K5: 1896390227 | L5: =K5-G5 -> 110184892 | M5: ='lamp. sk'!H13 -> 2063806264 | N5: =M5-I5 -> 2.771037e+08 | O5: =N5/I5 -> 0.15509224
B6: 2. | C6: Ambarketawang | D6: 1.3314457e+09 | E6: 1522442091 | F6: =E6-D6 -> 1.909964e+08 | G6: 1535741924 | H6: =G6-E6 -> 13299833 | I6: 1.5329372e+09 | J6: =I6-G6 -> -2804698.3 | K6: 1625366159 | L6: =K6-G6 -> 89624235 | M6: ='lamp. sk'!H14 -> 1782256046 | N6: =M6-I6 -> 2.4931882e+08 | O6: =N6/I6 -> 0.16264125
B7: 3. | C7: Banyuraden | D7: 1.021704e+09 | E7: 1164858211 | F7: =E7-D7 -> 1.4315421e+08 | G7: 1165210517 | H7: =G7-E7 -> 352306 | I7: 1.1665735e+09 | J7: =I7-G7 -> 1363013.4 | K7: 1242617644 | L7: =K7-G7 -> 77407127 | M7: ='lamp. sk'!H15 -> 1397500762 | N7: =M7-I7 -> 2.3092723e+08 | O7: =N7/I7 -> 0.19795343
B8: 4. | C8: Nogotirto | D8: 1.0090403e+09 | E8: 1130645410 | F8: =E8-D8 -> 121605149 | G8: 1134564912 | H8: =G8-E8 -> 3919502 | I8: 1.1355329e+09 | J8: =I8-G8 -> 968027.9 | K8: 1211679327 | L8: =K8-G8 -> 77114415 | M8: ='lamp. sk'!H16 -> 1386812721 | N8: =M8-I8 -> 2.5127978e+08 | O8: =N8/I8 -> 0.22128797
B9: 5. | C9: Trihanggo | D9: 1.23249e+09 | E9: 1413371888 | F9: =E9-D9 -> 1.8088193e+08 | G9: 1425476157 | H9: =G9-E9 -> 12104269 | I9: 1.4184544e+09 | J9: =I9-G9 -> -7021725.2 | K9: 1498929892 | L9: =K9-G9 -> 73453735 | M9: ='lamp. sk'!H17 -> 1666370328 | N9: =M9-I9 -> 2.479159e+08 | O9: =N9/I9 -> 0.17477889
B10: II. | C10: GODEAN
B11: 6. | C11: Sidorejo | D11: 1.0288005e+09 | E11: 1309731872 | F11: =E11-D11 -> 2.8093142e+08 | G11: 1300453454 | H11: =G11-E11 -> -9278418 | I11: 1.3021252e+09 | J11: =I11-G11 -> 1671740.3 | K11: 1388126258 | L11: =K11-G11 -> 87672804 | M11: ='lamp. sk'!H19 -> 1546741032 | N11: =M11-I11 -> 2.4461584e+08 | O11: =N11/I11 -> 0.18785892
B12: 7. | C12: Sidoluhur | D12: 1.1235985e+09 | E12: 1423338224 | F12: =E12-D12 -> 2.997397e+08 | G12: 1420058550 | H12: =G12-E12 -> -3279674 | I12: 1.4220942e+09 | J12: =I12-G12 -> 2035647.7 | K12: 1512620903 | L12: =K12-G12 -> 92562353 | M12: ='lamp. sk'!H20 -> 1722504251 | N12: =M12-I12 -> 3.0041005e+08 | O12: =N12/I12 -> 0.21124483
B13: 8. | C13: Sidomulyo | D13: 8.1548003e+08 | E13: 983565574 | F13: =E13-D13 -> 1.6808555e+08 | G13: 976345763 | H13: =G13-E13 -> -7219811 | I13: 9.7451406e+08 | J13: =I13-G13 -> -1831703.2 | K13: 1044338028 | L13: =K13-G13 -> 67992265 | M13: ='lamp. sk'!H21 -> 1199808625 | N13: =M13-I13 -> 2.2529457e+08 | O13: =N13/I13 -> 0.23118657
B14: 9. | C14: Sidoagung | D14: 8.4927611e+08 | E14: 1067613321 | F14: =E14-D14 -> 2.1833721e+08 | G14: 1031269903 | H14: =G14-E14 -> -36343418 | I14: 1032159322 | J14: =I14-G14 -> 889419 | K14: 1105500436 | L14: =K14-G14 -> 74230533 | M14: ='lamp. sk'!H22 -> 1298451866 | N14: =M14-I14 -> 266292544 | O14: =N14/I14 -> 0.25799558
B15: 10. | C15: Sidokarto | D15: 1.1294992e+09 | E15: 1378576540 | F15: =E15-D15 -> 2.4907739e+08 | G15: 1393652704 | H15: =G15-E15 -> 15076164 | I15: 1.3918384e+09 | J15: =I15-G15 -> -1814258.2 | K15: 1487297322 | L15: =K15-G15 -> 93644618 | M15: ='lamp. sk'!H23 -> 1675141901 | N15: =M15-I15 -> 2.8330346e+08 | O15: =N15/I15 -> 0.20354622
B16: 11. | C16: Sidoarum | D16: 1.0277724e+09 | E16: 1166661297 | F16: =E16-D16 -> 1.3888891e+08 | G16: 1182267083 | H16: =G16-E16 -> 15605786 | I16: 1.1815158e+09 | J16: =I16-G16 -> -751285.5 | K16: 1263560540 | L16: =K16-G16 -> 81293457 | M16: ='lamp. sk'!H24 -> 1418489233 | N16: =M16-I16 -> 2.3697344e+08 | O16: =N16/I16 -> 0.2005673
B17: 12. | C17: Sidomoyo | D17: 9.5294763e+08 | E17: 1173333040 | F17: =E17-D17 -> 2.2038541e+08 | G17: 1168563412 | H17: =G17-E17 -> -4769628 | I17: 1.1685481e+09 | J17: =I17-G17 -> -15315.5 | K17: 1244826511 | L17: =K17-G17 -> 76263099 | M17: ='lamp. sk'!H25 -> 1408511824 | N17: =M17-I17 -> 2.3996373e+08 | O17: =N17/I17 -> 0.20535203
B18: III. | C18: MOYUDAN
B19: 13. | C19: Sumberrahayu | D19: 1.1004329e+09 | E19: 1393181065 | F19: =E19-D19 -> 2.9274814e+08 | G19: 1389984649 | H19: =G19-E19 -> -3196416 | I19: 1.3897069e+09 | J19: =I19-G19 -> -277747.8 | K19: 1477281745 | L19: =K19-G19 -> 87297096 | M19: ='lamp. sk'!H28 -> 1645575109 | N19: =M19-I19 -> 2.5586821e+08 | O19: =N19/I19 -> 0.18411667
B20: 14. | C20: Sumbersari | D20: 1.0655916e+09 | E20: 1317651323 | F20: =E20-D20 -> 2.5205973e+08 | G20: 1314338525 | H20: =G20-E20 -> -3312798 | I20: 1.3095459e+09 | J20: =I20-G20 -> -4792629.9 | K20: 1399745247 | L20: =K20-G20 -> 85406722 | M20: ='lamp. sk'!H29 -> 1595150035 | N20: =M20-I20 -> 2.8560414e+08 | O20: =N20/I20 -> 0.21809403
